2022-12-21 10:11:57,084 fflow.py initialize [line:255] INFO Using Logger in `utils.logger.basic_logger`
2022-12-21 10:11:57,085 fflow.py initialize [line:256] INFO Initializing fedtask: pill_classification
2022-12-21 10:11:57,276 fflow.py initialize [line:272] INFO Using model `resnet18` in `benchmark.pill_classification.model.resnet18` as the globally shared model.
2022-12-21 10:11:57,277 fflow.py initialize [line:298] INFO Using sampler `threshold_sampler` in `sampler.threshold_sampler` as the globally shared model.
Using cache found in /home/aiotlabws/.cache/torch/hub/pytorch_vision_v0.10.0
2022-12-21 10:12:03,638 fflow.py initialize [line:318] INFO Initializing Clients: 10 clients of `algorithm.fedavg.Client` being created.
2022-12-21 10:12:03,640 fflow.py initialize [line:339] INFO Initializing Server: 1 server of `algorithm.fedavg.Server` being created.
2022-12-21 10:12:03,640 fflow.py initialize [line:352] INFO Ready to start.
2022-12-21 10:12:03,640 fedbase.py run [line:61] INFO --------------Round 1--------------
Client 1 init its dataloader
2022-12-21 10:12:07,488 basic_logger.py show_current_output [line:134] INFO test_accuracy                 0.0130
2022-12-21 10:12:07,489 basic_logger.py show_current_output [line:134] INFO test_loss                     4.5173
2022-12-21 10:12:07,489 basic_logger.py time_end [line:74] INFO Eval Time Cost:               3.8486s
2022-12-21 10:12:07,490 fedbase.py iterate [line:106] INFO Selected clients : [1, 2]
Client 2 init its dataloader
Using cache found in /home/aiotlabws/.cache/torch/hub/pytorch_vision_v0.10.0
2022-12-21 10:13:13,308 main.py main [line:25] ERROR Exception Logged
Traceback (most recent call last):
  File "main.py", line 22, in main
    try:
  File "/mnt/disk2/ndlong/easyFL/algorithm/fedbase.py", line 82, in run
    utils.fmodule.save_json(self.log_file, f'{self.option["log_result_path"]}/{self.option["group_name"]}',self.option["session_name"])
  File "/mnt/disk2/ndlong/easyFL/utils/fmodule.py", line 22, in save_json
    json.dump(json_dict, f)
  File "/mnt/disk1/anaconda3/envs/longnd/lib/python3.8/json/__init__.py", line 179, in dump
    for chunk in iterable:
  File "/mnt/disk1/anaconda3/envs/longnd/lib/python3.8/json/encoder.py", line 431, in _iterencode
    yield from _iterencode_dict(o, _current_indent_level)
  File "/mnt/disk1/anaconda3/envs/longnd/lib/python3.8/json/encoder.py", line 405, in _iterencode_dict
    yield from chunks
  File "/mnt/disk1/anaconda3/envs/longnd/lib/python3.8/json/encoder.py", line 405, in _iterencode_dict
    yield from chunks
  File "/mnt/disk1/anaconda3/envs/longnd/lib/python3.8/json/encoder.py", line 325, in _iterencode_list
    yield from chunks
  File "/mnt/disk1/anaconda3/envs/longnd/lib/python3.8/json/encoder.py", line 438, in _iterencode
    o = _default(o)
  File "/mnt/disk1/anaconda3/envs/longnd/lib/python3.8/json/encoder.py", line 179, in default
    raise TypeError(f'Object of type {o.__class__.__name__} '
TypeError: Object of type int64 is not JSON serializable
Traceback (most recent call last):
  File "main.py", line 22, in main
    try:
  File "/mnt/disk2/ndlong/easyFL/algorithm/fedbase.py", line 82, in run
    utils.fmodule.save_json(self.log_file, f'{self.option["log_result_path"]}/{self.option["group_name"]}',self.option["session_name"])
  File "/mnt/disk2/ndlong/easyFL/utils/fmodule.py", line 22, in save_json
    json.dump(json_dict, f)
  File "/mnt/disk1/anaconda3/envs/longnd/lib/python3.8/json/__init__.py", line 179, in dump
    for chunk in iterable:
  File "/mnt/disk1/anaconda3/envs/longnd/lib/python3.8/json/encoder.py", line 431, in _iterencode
    yield from _iterencode_dict(o, _current_indent_level)
  File "/mnt/disk1/anaconda3/envs/longnd/lib/python3.8/json/encoder.py", line 405, in _iterencode_dict
    yield from chunks
  File "/mnt/disk1/anaconda3/envs/longnd/lib/python3.8/json/encoder.py", line 405, in _iterencode_dict
    yield from chunks
  File "/mnt/disk1/anaconda3/envs/longnd/lib/python3.8/json/encoder.py", line 325, in _iterencode_list
    yield from chunks
  File "/mnt/disk1/anaconda3/envs/longnd/lib/python3.8/json/encoder.py", line 438, in _iterencode
    o = _default(o)
  File "/mnt/disk1/anaconda3/envs/longnd/lib/python3.8/json/encoder.py", line 179, in default
    raise TypeError(f'Object of type {o.__class__.__name__} '
TypeError: Object of type int64 is not JSON serializable
During handling of the above exception, another exception occurred:
Traceback (most recent call last):
  File "main.py", line 31, in <module>
    # torch.multiprocessing.set_sharing_strategy('file_system')
  File "main.py", line 26, in main
    flw.logger.exception("Exception Logged")
RuntimeError