wandb: Currently logged in as: longnd (aiotlab). Use `wandb login --relogin` to force relogin
wandb: wandb version 0.13.7 is available!  To upgrade, please run:
wandb:  $ pip install wandb --upgrade
wandb: Tracking run with wandb version 0.13.5
wandb: Run data is saved locally in /home/ace15032jo/Projects/repo2/SampleSelection_easyFL/wandb/run-20230104_200818-34r9ktxh
wandb: Run `wandb offline` to turn off syncing.
wandb: Syncing run fedalgo1_fedprox_ratio_0.8_C_0.5_
wandb: ‚≠êÔ∏è View project at https://wandb.ai/aiotlab/Abnormal_Data_FL
wandb: üöÄ View run at https://wandb.ai/aiotlab/Abnormal_Data_FL/runs/34r9ktxh
2023-01-04 20:08:20,011 fflow.py initialize [line:262] INFO Using Logger in `utils.logger.basic_logger`
2023-01-04 20:08:20,012 fflow.py initialize [line:263] INFO Initializing fedtask: pill_classification
2023-01-04 20:08:20,456 fflow.py initialize [line:279] INFO Using model `resnet18` in `benchmark.pill_classification.model.resnet18` as the globally shared model.
2023-01-04 20:08:20,461 fflow.py initialize [line:307] INFO Using sampler `threshold_sampler` in `sampler.threshold_sampler` as the globally shared model.
Using cache found in /home/ace15032jo/.cache/torch/hub/pytorch_vision_v0.10.0
2023-01-04 20:08:26,998 fflow.py initialize [line:327] INFO Initializing Clients: 10 clients of `algorithm.fedalgo1_fedprox.Client` being created.
2023-01-04 20:08:27,000 fflow.py initialize [line:348] INFO Initializing Server: 1 server of `algorithm.fedalgo1_fedprox.Server` being created.
2023-01-04 20:08:27,000 fflow.py initialize [line:361] INFO Ready to start.
2023-01-04 20:08:27,000 fedbase.py run [line:63] INFO --------------Round 1--------------
2023-01-04 20:08:30,261 basic_logger.py show_current_output [line:147] INFO test_accuracy                 0.0130
2023-01-04 20:08:30,264 basic_logger.py show_current_output [line:147] INFO test_loss                     4.5173
2023-01-04 20:08:30,264 basic_logger.py time_end [line:77] INFO Eval Time Cost:               3.2643s
2023-01-04 20:08:30,274 fedalgo1_fedprox.py iterate [line:21] INFO Selected clients : [1, 2, 7, 3, 5]
2023-01-04 20:08:30,274 main.py main [line:27] ERROR Exception Logged
Traceback (most recent call last):
  File "/home/ace15032jo/Projects/repo2/SampleSelection_easyFL/main.py", line 24, in main
    server.run()
  File "/home/ace15032jo/Projects/repo2/SampleSelection_easyFL/algorithm/fedbase.py", line 76, in run
    self.iterate()
  File "/home/ace15032jo/Projects/repo2/SampleSelection_easyFL/algorithm/fedalgo1_fedprox.py", line 22, in iterate
    threshold_score = self.cal_threshold(self.selected_clients)
  File "/home/ace15032jo/Projects/repo2/SampleSelection_easyFL/algorithm/fedalgo1_fedprox.py", line 130, in cal_threshold
    self.calculate_importance(selected_clinets)
  File "/home/ace15032jo/Projects/repo2/SampleSelection_easyFL/algorithm/fedalgo1_fedprox.py", line 116, in calculate_importance
    cpkqs = [self.communicate_score_with(cid) for id, cid in enumerate(selected_clients)]
  File "/home/ace15032jo/Projects/repo2/SampleSelection_easyFL/algorithm/fedalgo1_fedprox.py", line 116, in <listcomp>
    cpkqs = [self.communicate_score_with(cid) for id, cid in enumerate(selected_clients)]
  File "/home/ace15032jo/Projects/repo2/SampleSelection_easyFL/algorithm/fedalgo1_fedprox.py", line 126, in communicate_score_with
    svr_pkg = self.pack(client_id)
AttributeError: 'Server' object has no attribute 'pack'
Traceback (most recent call last):
  File "/home/ace15032jo/Projects/repo2/SampleSelection_easyFL/main.py", line 24, in main
    server.run()
  File "/home/ace15032jo/Projects/repo2/SampleSelection_easyFL/algorithm/fedbase.py", line 76, in run
    self.iterate()
  File "/home/ace15032jo/Projects/repo2/SampleSelection_easyFL/algorithm/fedalgo1_fedprox.py", line 22, in iterate
    threshold_score = self.cal_threshold(self.selected_clients)
  File "/home/ace15032jo/Projects/repo2/SampleSelection_easyFL/algorithm/fedalgo1_fedprox.py", line 130, in cal_threshold
    self.calculate_importance(selected_clinets)
  File "/home/ace15032jo/Projects/repo2/SampleSelection_easyFL/algorithm/fedalgo1_fedprox.py", line 116, in calculate_importance
    cpkqs = [self.communicate_score_with(cid) for id, cid in enumerate(selected_clients)]
  File "/home/ace15032jo/Projects/repo2/SampleSelection_easyFL/algorithm/fedalgo1_fedprox.py", line 116, in <listcomp>
    cpkqs = [self.communicate_score_with(cid) for id, cid in enumerate(selected_clients)]
  File "/home/ace15032jo/Projects/repo2/SampleSelection_easyFL/algorithm/fedalgo1_fedprox.py", line 126, in communicate_score_with
    svr_pkg = self.pack(client_id)
AttributeError: 'Server' object has no attribute 'pack'

During handling of the above exception, another exception occurred:

Traceback (most recent call last):
  File "/home/ace15032jo/Projects/repo2/SampleSelection_easyFL/main.py", line 33, in <module>
    main()
  File "/home/ace15032jo/Projects/repo2/SampleSelection_easyFL/main.py", line 28, in main
    raise RuntimeError
RuntimeError
wandb: Waiting for W&B process to finish... (failed 1). Press Control-C to abort syncing.
wandb: - 0.010 MB of 0.010 MB uploaded (0.000 MB deduped)wandb: \ 0.010 MB of 0.014 MB uploaded (0.000 MB deduped)wandb: | 0.018 MB of 0.018 MB uploaded (0.000 MB deduped)wandb: 
wandb: Run history:
wandb: Accuracy/Testing Accuracy ‚ñÅ
wandb:         Loss/Testing Loss ‚ñÅ
wandb: 
wandb: Run summary:
wandb: Accuracy/Testing Accuracy 0.01299
wandb:         Loss/Testing Loss 4.51729
wandb: 
wandb: Synced fedalgo1_fedprox_ratio_0.8_C_0.5_: https://wandb.ai/aiotlab/Abnormal_Data_FL/runs/34r9ktxh
wandb: Synced 5 W&B file(s), 0 media file(s), 0 artifact file(s) and 0 other file(s)
wandb: Find logs at: ./wandb/run-20230104_200818-34r9ktxh/logs
