wandb: Currently logged in as: longnd (aiotlab). Use `wandb login --relogin` to force relogin
wandb: wandb version 0.13.11 is available!  To upgrade, please run:
wandb:  $ pip install wandb --upgrade
wandb: Tracking run with wandb version 0.13.5
wandb: Run data is saved locally in /home/ace15032jo/Projects/repo2/SampleSelection_easyFL/wandb/run-20230312_192314-3okg4pjh
wandb: Run `wandb offline` to turn off syncing.
wandb: Syncing run fedavg_v1_loss_based_ratio_1.0_C_0.3_baseline_loss
wandb: ‚≠êÔ∏è View project at https://wandb.ai/aiotlab/Abnormal_Data_FL
wandb: üöÄ View run at https://wandb.ai/aiotlab/Abnormal_Data_FL/runs/3okg4pjh
2023-03-12 19:23:15,252 fflow.py initialize [line:270] INFO Using Logger in `utils.logger.basic_logger`
2023-03-12 19:23:15,252 fflow.py initialize [line:271] INFO Initializing fedtask: cifar10_classification
2023-03-12 19:23:16,309 fflow.py initialize [line:287] INFO Using model `resnet18` in `benchmark.cifar10_classification.model.resnet18` as the globally shared model.
2023-03-12 19:23:16,315 fflow.py initialize [line:315] INFO Using sampler `threshold_sampler` in `sampler.threshold_sampler` as the globally shared model.
2023-03-12 19:23:22,070 fflow.py initialize [line:339] INFO Initializing Clients: 100 clients of `algorithm.fedavg_v1_loss_based.Client` being created.
2023-03-12 19:23:22,073 fflow.py initialize [line:360] INFO Initializing Server: 1 server of `algorithm.fedavg_v1_loss_based.Server` being created.
2023-03-12 19:23:22,073 fflow.py initialize [line:373] INFO Ready to start.
2023-03-12 19:23:22,073 fedbase.py run [line:64] INFO --------------Round 1--------------
2023-03-12 19:23:29,997 basic_logger.py show_current_output [line:148] INFO test_accuracy                 0.0939
2023-03-12 19:23:29,997 basic_logger.py show_current_output [line:148] INFO test_loss                     2.3042
2023-03-12 19:23:29,997 basic_logger.py time_end [line:78] INFO Eval Time Cost:               7.9235s
2023-03-12 19:23:30,000 fedavg_v1_loss_based.py iterate [line:39] INFO Selected clients : [23, 81, 85, 34, 62, 46, 42, 31, 93, 11, 22, 77, 66, 13, 10, 68, 27, 36, 86, 40, 19, 1, 3, 16, 17, 29, 49, 45, 58, 37]
>>>>>> Using cifar10 dataset
Files already downloaded and verified
Client 1 init its dataloader
Client 3 init its dataloader
Client 10 init its dataloader
Client 11 init its dataloader
Client 13 init its dataloader
Client 16 init its dataloader
Client 17 init its dataloader
Client 19 init its dataloader
Client 22 init its dataloader
Client 23 init its dataloader
Client 27 init its dataloader
Client 29 init its dataloader
Client 31 init its dataloader
Client 34 init its dataloader
Client 36 init its dataloader
Client 37 init its dataloader
Client 40 init its dataloader
Client 42 init its dataloader
Client 45 init its dataloader
Client 46 init its dataloader
Client 49 init its dataloader
Client 58 init its dataloader
Client 62 init its dataloader
Client 66 init its dataloader
Client 68 init its dataloader
Client 77 init its dataloader
Client 81 init its dataloader
Client 85 init its dataloader
Client 86 init its dataloader
Client 93 init its dataloader
> /home/ace15032jo/Projects/repo2/SampleSelection_easyFL/algorithm/fedavg_v1_loss_based.py(54)iterate()
-> print(
(Pdb) 2023-03-12 19:28:14,612 main.py main [line:27] ERROR Exception Logged
Traceback (most recent call last):
  File "/home/ace15032jo/Projects/repo2/SampleSelection_easyFL/main.py", line 24, in main
    server.run()
  File "/home/ace15032jo/Projects/repo2/SampleSelection_easyFL/algorithm/fedbase.py", line 77, in run
    self.iterate()
  File "/home/ace15032jo/Projects/repo2/SampleSelection_easyFL/algorithm/fedavg_v1_loss_based.py", line 54, in iterate
    print(
  File "/home/ace15032jo/Projects/repo2/SampleSelection_easyFL/algorithm/fedavg_v1_loss_based.py", line 54, in iterate
    print(
  File "/apps/centos7/python/3.10.4_gcc11.2.0/lib/python3.10/bdb.py", line 90, in trace_dispatch
    return self.dispatch_line(frame)
  File "/apps/centos7/python/3.10.4_gcc11.2.0/lib/python3.10/bdb.py", line 115, in dispatch_line
    if self.quitting: raise BdbQuit
bdb.BdbQuit

Traceback (most recent call last):
  File "/home/ace15032jo/Projects/repo2/SampleSelection_easyFL/main.py", line 24, in main
    server.run()
  File "/home/ace15032jo/Projects/repo2/SampleSelection_easyFL/algorithm/fedbase.py", line 77, in run
    self.iterate()
  File "/home/ace15032jo/Projects/repo2/SampleSelection_easyFL/algorithm/fedavg_v1_loss_based.py", line 54, in iterate
    print(
  File "/home/ace15032jo/Projects/repo2/SampleSelection_easyFL/algorithm/fedavg_v1_loss_based.py", line 54, in iterate
    print(
  File "/apps/centos7/python/3.10.4_gcc11.2.0/lib/python3.10/bdb.py", line 90, in trace_dispatch
    return self.dispatch_line(frame)
  File "/apps/centos7/python/3.10.4_gcc11.2.0/lib/python3.10/bdb.py", line 115, in dispatch_line
    if self.quitting: raise BdbQuit
bdb.BdbQuit

During handling of the above exception, another exception occurred:

Traceback (most recent call last):
  File "/home/ace15032jo/Projects/repo2/SampleSelection_easyFL/main.py", line 33, in <module>
    main()
  File "/home/ace15032jo/Projects/repo2/SampleSelection_easyFL/main.py", line 28, in main
    raise RuntimeError
RuntimeError
wandb: Waiting for W&B process to finish... (failed 1). Press Control-C to abort syncing.
wandb: 
wandb: Run history:
wandb: Accuracy/Testing Accuracy ‚ñÅ
wandb:         Loss/Testing Loss ‚ñÅ
wandb: 
wandb: Run summary:
wandb: Accuracy/Testing Accuracy 0.0939
wandb:         Loss/Testing Loss 2.30424
wandb: 
wandb: Synced fedavg_v1_loss_based_ratio_1.0_C_0.3_baseline_loss: https://wandb.ai/aiotlab/Abnormal_Data_FL/runs/3okg4pjh
wandb: Synced 5 W&B file(s), 0 media file(s), 0 artifact file(s) and 0 other file(s)
wandb: Find logs at: ./wandb/run-20230312_192314-3okg4pjh/logs
