wandb: Currently logged in as: longnd (aiotlab). Use `wandb login --relogin` to force relogin
wandb: wandb version 0.13.11 is available!  To upgrade, please run:
wandb:  $ pip install wandb --upgrade
wandb: Tracking run with wandb version 0.13.5
wandb: Run data is saved locally in /home/ace15032jo/Projects/repo2/SampleSelection_easyFL/wandb/run-20230313_014330-2weq1i2f
wandb: Run `wandb offline` to turn off syncing.
wandb: Syncing run fedavg_v1_random_choice_ratio_1.0_C_0.3_baseline_random
wandb: ‚≠êÔ∏è View project at https://wandb.ai/aiotlab/Abnormal_Data_FL
wandb: üöÄ View run at https://wandb.ai/aiotlab/Abnormal_Data_FL/runs/2weq1i2f
2023-03-13 01:43:32,106 fflow.py initialize [line:270] INFO Using Logger in `utils.logger.basic_logger`
2023-03-13 01:43:32,106 fflow.py initialize [line:271] INFO Initializing fedtask: cifar10_classification
2023-03-13 01:43:33,123 fflow.py initialize [line:287] INFO Using model `resnet18` in `benchmark.cifar10_classification.model.resnet18` as the globally shared model.
2023-03-13 01:43:33,130 fflow.py initialize [line:315] INFO Using sampler `threshold_sampler` in `sampler.threshold_sampler` as the globally shared model.
2023-03-13 01:43:39,276 fflow.py initialize [line:339] INFO Initializing Clients: 100 clients of `algorithm.fedavg_v1_random_choice.Client` being created.
2023-03-13 01:43:39,279 fflow.py initialize [line:360] INFO Initializing Server: 1 server of `algorithm.fedavg_v1_random_choice.Server` being created.
2023-03-13 01:43:39,280 fflow.py initialize [line:373] INFO Ready to start.
2023-03-13 01:43:39,280 fedbase.py run [line:64] INFO --------------Round 1--------------
2023-03-13 01:43:47,502 basic_logger.py show_current_output [line:148] INFO test_accuracy                 0.0939
2023-03-13 01:43:47,502 basic_logger.py show_current_output [line:148] INFO test_loss                     2.3042
2023-03-13 01:43:47,502 basic_logger.py time_end [line:78] INFO Eval Time Cost:               8.2221s
2023-03-13 01:43:47,505 fedavg_v1_random_choice.py iterate [line:39] INFO Selected clients : [23, 81, 85, 34, 62, 46, 42, 31, 93, 11, 22, 77, 66, 13, 10, 68, 27, 36, 86, 40, 19, 1, 3, 16, 17, 29, 49, 45, 58, 37]
2023-03-13 01:43:56,989 main.py main [line:27] ERROR Exception Logged
Traceback (most recent call last):
  File "/home/ace15032jo/Projects/repo2/SampleSelection_easyFL/main.py", line 24, in main
    server.run()
  File "/home/ace15032jo/Projects/repo2/SampleSelection_easyFL/algorithm/fedbase.py", line 77, in run
    self.iterate()
  File "/home/ace15032jo/Projects/repo2/SampleSelection_easyFL/algorithm/fedavg_v1_random_choice.py", line 44, in iterate
    received_information = self.communicate(self.selected_clients)
  File "/home/ace15032jo/Projects/repo2/SampleSelection_easyFL/algorithm/fedbase.py", line 143, in communicate
    response_from_client_id = self.communicate_with(client_id)
  File "/home/ace15032jo/Projects/repo2/SampleSelection_easyFL/algorithm/fedbase.py", line 167, in communicate_with
    return self.clients[client_id].reply(svr_pkg)
  File "/home/ace15032jo/Projects/repo2/SampleSelection_easyFL/algorithm/fedbase.py", line 499, in reply
    cpkg = self.pack(model)
  File "/home/ace15032jo/Projects/repo2/SampleSelection_easyFL/algorithm/fedavg_v1_random_choice.py", line 142, in pack
    "n_samples": len(self.current_dataset),
AttributeError: 'Client' object has no attribute 'current_dataset'
>>>>>> Using cifar10 dataset
Files already downloaded and verified
Client 1 init its dataloader
Traceback (most recent call last):
  File "/home/ace15032jo/Projects/repo2/SampleSelection_easyFL/main.py", line 24, in main
    server.run()
  File "/home/ace15032jo/Projects/repo2/SampleSelection_easyFL/algorithm/fedbase.py", line 77, in run
    self.iterate()
  File "/home/ace15032jo/Projects/repo2/SampleSelection_easyFL/algorithm/fedavg_v1_random_choice.py", line 44, in iterate
    received_information = self.communicate(self.selected_clients)
  File "/home/ace15032jo/Projects/repo2/SampleSelection_easyFL/algorithm/fedbase.py", line 143, in communicate
    response_from_client_id = self.communicate_with(client_id)
  File "/home/ace15032jo/Projects/repo2/SampleSelection_easyFL/algorithm/fedbase.py", line 167, in communicate_with
    return self.clients[client_id].reply(svr_pkg)
  File "/home/ace15032jo/Projects/repo2/SampleSelection_easyFL/algorithm/fedbase.py", line 499, in reply
    cpkg = self.pack(model)
  File "/home/ace15032jo/Projects/repo2/SampleSelection_easyFL/algorithm/fedavg_v1_random_choice.py", line 142, in pack
    "n_samples": len(self.current_dataset),
AttributeError: 'Client' object has no attribute 'current_dataset'

During handling of the above exception, another exception occurred:

Traceback (most recent call last):
  File "/home/ace15032jo/Projects/repo2/SampleSelection_easyFL/main.py", line 33, in <module>
    main()
  File "/home/ace15032jo/Projects/repo2/SampleSelection_easyFL/main.py", line 28, in main
    raise RuntimeError
RuntimeError
wandb: Waiting for W&B process to finish... (failed 1). Press Control-C to abort syncing.
wandb: 
wandb: Run history:
wandb: Accuracy/Testing Accuracy ‚ñÅ
wandb:         Loss/Testing Loss ‚ñÅ
wandb: 
wandb: Run summary:
wandb: Accuracy/Testing Accuracy 0.0939
wandb:         Loss/Testing Loss 2.30424
wandb: 
wandb: Synced fedavg_v1_random_choice_ratio_1.0_C_0.3_baseline_random: https://wandb.ai/aiotlab/Abnormal_Data_FL/runs/2weq1i2f
wandb: Synced 5 W&B file(s), 0 media file(s), 0 artifact file(s) and 0 other file(s)
wandb: Find logs at: ./wandb/run-20230313_014330-2weq1i2f/logs
