2022-12-21 10:18:58,026 fflow.py initialize [line:255] INFO Using Logger in `utils.logger.basic_logger`
2022-12-21 10:18:58,026 fflow.py initialize [line:256] INFO Initializing fedtask: pill_classification
2022-12-21 10:18:58,195 fflow.py initialize [line:272] INFO Using model `resnet18` in `benchmark.pill_classification.model.resnet18` as the globally shared model.
2022-12-21 10:18:58,196 fflow.py initialize [line:298] INFO Using sampler `threshold_sampler` in `sampler.threshold_sampler` as the globally shared model.
Using cache found in /home/aiotlabws/.cache/torch/hub/pytorch_vision_v0.10.0
2022-12-21 10:19:04,544 fflow.py initialize [line:318] INFO Initializing Clients: 10 clients of `algorithm.fedavg.Client` being created.
2022-12-21 10:19:04,545 fflow.py initialize [line:339] INFO Initializing Server: 1 server of `algorithm.fedavg.Server` being created.
2022-12-21 10:19:04,546 fflow.py initialize [line:352] INFO Ready to start.
2022-12-21 10:19:04,546 fedbase.py run [line:61] INFO --------------Round 1--------------
2022-12-21 10:19:08,891 basic_logger.py show_current_output [line:134] INFO test_accuracy                 0.0130
2022-12-21 10:19:08,892 basic_logger.py show_current_output [line:134] INFO test_loss                     4.5173
2022-12-21 10:19:08,892 basic_logger.py time_end [line:74] INFO Eval Time Cost:               4.3458s
2022-12-21 10:19:08,893 fedbase.py iterate [line:107] INFO Selected clients : [1, 2]
Client 1 init its dataloader
Client 2 init its dataloader
Using cache found in /home/aiotlabws/.cache/torch/hub/pytorch_vision_v0.10.0
> /mnt/disk2/ndlong/easyFL/algorithm/fedbase.py(82)run()
-> self.log_file[f"Round {round}"] = utils.fmodule.LOG_DICT
2022-12-21 10:20:08,139 basic_logger.py time_end [line:74] INFO Time Cost:                    63.5933s
2022-12-21 10:20:08,140 fedbase.py run [line:82] INFO --------------Round 2--------------
2022-12-21 10:20:10,877 basic_logger.py show_current_output [line:134] INFO test_accuracy                 0.2701
2022-12-21 10:20:10,878 basic_logger.py show_current_output [line:134] INFO test_loss                     3.3426
2022-12-21 10:20:10,879 basic_logger.py time_end [line:74] INFO Eval Time Cost:               2.7375s
2022-12-21 10:20:10,879 fedbase.py iterate [line:107] INFO Selected clients : [3, 0]
Client 0 init its dataloader
Client 3 init its dataloader
Using cache found in /home/aiotlabws/.cache/torch/hub/pytorch_vision_v0.10.0
> /mnt/disk2/ndlong/easyFL/algorithm/fedbase.py(81)run()
-> breakpoint()
2022-12-21 10:20:58,484 basic_logger.py time_end [line:74] INFO Time Cost:                    50.3432s
2022-12-21 10:20:58,485 fedbase.py run [line:81] INFO --------------Round 3--------------
2022-12-21 10:21:00,925 basic_logger.py show_current_output [line:134] INFO test_accuracy                 0.2805
2022-12-21 10:21:00,925 basic_logger.py show_current_output [line:134] INFO test_loss                     3.2596
2022-12-21 10:21:00,925 basic_logger.py time_end [line:74] INFO Eval Time Cost:               2.4401s
2022-12-21 10:21:00,926 fedbase.py iterate [line:107] INFO Selected clients : [1, 2]
Using cache found in /home/aiotlabws/.cache/torch/hub/pytorch_vision_v0.10.0
> /mnt/disk2/ndlong/easyFL/algorithm/fedbase.py(82)run()
-> self.log_file[f"Round {round}"] = utils.fmodule.LOG_DICT
2022-12-21 10:26:21,070 main.py main [line:24] ERROR Exception Logged
Traceback (most recent call last):
  File "main.py", line 24, in main
    server.run()
  File "/mnt/disk2/ndlong/easyFL/algorithm/fedbase.py", line 82, in run
    self.log_file[f"Round {round}"] = utils.fmodule.LOG_DICT
  File "/mnt/disk2/ndlong/easyFL/algorithm/fedbase.py", line 82, in run
    self.log_file[f"Round {round}"] = utils.fmodule.LOG_DICT
  File "/mnt/disk1/anaconda3/envs/longnd/lib/python3.8/bdb.py", line 88, in trace_dispatch
    return self.dispatch_line(frame)
  File "/mnt/disk1/anaconda3/envs/longnd/lib/python3.8/bdb.py", line 113, in dispatch_line
    if self.quitting: raise BdbQuit
bdb.BdbQuit
Traceback (most recent call last):
  File "main.py", line 24, in main
    server.run()
  File "/mnt/disk2/ndlong/easyFL/algorithm/fedbase.py", line 82, in run
    self.log_file[f"Round {round}"] = utils.fmodule.LOG_DICT
  File "/mnt/disk2/ndlong/easyFL/algorithm/fedbase.py", line 82, in run
    self.log_file[f"Round {round}"] = utils.fmodule.LOG_DICT
  File "/mnt/disk1/anaconda3/envs/longnd/lib/python3.8/bdb.py", line 88, in trace_dispatch
    return self.dispatch_line(frame)
  File "/mnt/disk1/anaconda3/envs/longnd/lib/python3.8/bdb.py", line 113, in dispatch_line
    if self.quitting: raise BdbQuit
bdb.BdbQuit
During handling of the above exception, another exception occurred:
Traceback (most recent call last):
  File "main.py", line 33, in <module>
    main()
  File "main.py", line 24, in main
    server.run()
RuntimeError