2022-12-21 09:54:50,528 fflow.py initialize [line:249] INFO Using Logger in `utils.logger.basic_logger`
2022-12-21 09:54:50,529 fflow.py initialize [line:250] INFO Initializing fedtask: pill_classification
2022-12-21 09:54:50,673 fflow.py initialize [line:266] INFO Using model `resnet18` in `benchmark.pill_classification.model.resnet18` as the globally shared model.
2022-12-21 09:54:50,674 fflow.py initialize [line:292] INFO Using sampler `threshold_sampler` in `sampler.threshold_sampler` as the globally shared model.
Using cache found in /home/aiotlabws/.cache/torch/hub/pytorch_vision_v0.10.0
2022-12-21 09:54:57,051 fflow.py initialize [line:312] INFO Initializing Clients: 10 clients of `algorithm.fedavg.Client` being created.
2022-12-21 09:54:57,053 fflow.py initialize [line:333] INFO Initializing Server: 1 server of `algorithm.fedavg.Server` being created.
2022-12-21 09:54:57,053 fflow.py initialize [line:346] INFO Ready to start.
2022-12-21 09:54:57,053 fedbase.py run [line:60] INFO --------------Round 1--------------
2022-12-21 09:55:01,083 basic_logger.py show_current_output [line:134] INFO test_accuracy                 0.0130
2022-12-21 09:55:01,084 basic_logger.py show_current_output [line:134] INFO test_loss                     4.5173
2022-12-21 09:55:01,085 basic_logger.py time_end [line:74] INFO Eval Time Cost:               4.0311s
> /mnt/disk2/ndlong/easyFL/algorithm/fedbase.py(71)run()
-> if flw.logger.early_stop():
*** NameError: name 'list_training_loss' is not defined
Client 1 init its dataloader
2022-12-21 09:55:12,301 fedbase.py iterate [line:97] INFO Selected clients : [1, 2]
Client 2 init its dataloader
Using cache found in /home/aiotlabws/.cache/torch/hub/pytorch_vision_v0.10.0
2022-12-21 09:56:10,229 basic_logger.py time_end [line:74] INFO Time Cost:                    73.1757s
2022-12-21 09:56:10,230 fedbase.py run [line:71] INFO --------------Round 2--------------
> /mnt/disk2/ndlong/easyFL/algorithm/fedbase.py(70)run()
-> breakpoint()
2022-12-21 09:56:13,154 basic_logger.py show_current_output [line:134] INFO test_accuracy                 0.2701
2022-12-21 09:56:13,155 basic_logger.py show_current_output [line:134] INFO test_loss                     3.3426
2022-12-21 09:56:13,155 basic_logger.py time_end [line:74] INFO Eval Time Cost:               2.9239s
2022-12-21 10:02:49,726 main.py main [line:22] ERROR Exception Logged
Traceback (most recent call last):
  File "main.py", line 22, in main
    server.run()
  File "/mnt/disk2/ndlong/easyFL/algorithm/fedbase.py", line 70, in run
    breakpoint()
  File "/mnt/disk2/ndlong/easyFL/algorithm/fedbase.py", line 70, in run
    breakpoint()
  File "/mnt/disk1/anaconda3/envs/longnd/lib/python3.8/bdb.py", line 88, in trace_dispatch
    return self.dispatch_line(frame)
  File "/mnt/disk1/anaconda3/envs/longnd/lib/python3.8/bdb.py", line 113, in dispatch_line
    if self.quitting: raise BdbQuit
bdb.BdbQuit
Traceback (most recent call last):
  File "main.py", line 22, in main
    server.run()
  File "/mnt/disk2/ndlong/easyFL/algorithm/fedbase.py", line 70, in run
    breakpoint()
  File "/mnt/disk2/ndlong/easyFL/algorithm/fedbase.py", line 70, in run
    breakpoint()
  File "/mnt/disk1/anaconda3/envs/longnd/lib/python3.8/bdb.py", line 88, in trace_dispatch
    return self.dispatch_line(frame)
  File "/mnt/disk1/anaconda3/envs/longnd/lib/python3.8/bdb.py", line 113, in dispatch_line
    if self.quitting: raise BdbQuit
bdb.BdbQuit
During handling of the above exception, another exception occurred:
Traceback (most recent call last):
  File "main.py", line 31, in <module>
    main()
  File "main.py", line 22, in main
    server.run()
RuntimeError