2022-12-21 09:49:27,052 INFO    StreamThr :25623 [internal.py:wandb_internal():88] W&B internal server running at pid: 25623, started at: 2022-12-21 09:49:27.050890
2022-12-21 09:49:27,054 DEBUG   HandlerThread:25623 [handler.py:handle_request():139] handle_request: status
2022-12-21 09:49:27,056 DEBUG   SenderThread:25623 [sender.py:send_request():317] send_request: status
2022-12-21 09:49:27,059 DEBUG   SenderThread:25623 [sender.py:send():303] send: header
2022-12-21 09:49:27,059 INFO    WriterThread:25623 [datastore.py:open_for_write():75] open: /mnt/disk2/ndlong/easyFL/wandb/run-20221221_094927-19xo4cf3/run-19xo4cf3.wandb
2022-12-21 09:49:27,082 DEBUG   SenderThread:25623 [sender.py:send():303] send: run
2022-12-21 09:49:27,798 ERROR   SenderThread:25623 [internal_api.py:execute():213] 404 response executing GraphQL.
2022-12-21 09:49:27,801 ERROR   SenderThread:25623 [internal_api.py:execute():214] {"errors":[{"message":"project not found","path":["upsertBucket"]}],"data":{"upsertBucket":null}}
2022-12-21 09:49:28,083 INFO    WriterThread:25623 [datastore.py:close():279] close: /mnt/disk2/ndlong/easyFL/wandb/run-20221221_094927-19xo4cf3/run-19xo4cf3.wandb
2022-12-21 09:49:28,083 INFO    HandlerThread:25623 [handler.py:finish():814] shutting down handler
2022-12-21 09:49:28,083 ERROR   StreamThr :25623 [internal.py:wandb_internal():163] Thread SenderThread:
Traceback (most recent call last):
  File "/mnt/disk1/anaconda3/envs/longnd/lib/python3.8/site-packages/wandb/sdk/lib/retry.py", line 113, in __call__
    result = self._call_fn(*args, **kwargs)
  File "/mnt/disk1/anaconda3/envs/longnd/lib/python3.8/site-packages/wandb/sdk/internal/internal_api.py", line 210, in execute
    return self.client.execute(*args, **kwargs)  # type: ignore
  File "/mnt/disk1/anaconda3/envs/longnd/lib/python3.8/site-packages/wandb/vendor/gql-0.2.0/wandb_gql/client.py", line 52, in execute
    result = self._get_result(document, *args, **kwargs)
  File "/mnt/disk1/anaconda3/envs/longnd/lib/python3.8/site-packages/wandb/vendor/gql-0.2.0/wandb_gql/client.py", line 60, in _get_result
    return self.transport.execute(document, *args, **kwargs)
  File "/mnt/disk1/anaconda3/envs/longnd/lib/python3.8/site-packages/wandb/vendor/gql-0.2.0/wandb_gql/transport/requests.py", line 39, in execute
    request.raise_for_status()
  File "/mnt/disk1/anaconda3/envs/longnd/lib/python3.8/site-packages/requests/models.py", line 1021, in raise_for_status
    raise HTTPError(http_error_msg, response=self)
requests.exceptions.HTTPError: 404 Client Error: Not Found for url: https://api.wandb.ai/graphql

During handling of the above exception, another exception occurred:

Traceback (most recent call last):
  File "/mnt/disk1/anaconda3/envs/longnd/lib/python3.8/site-packages/wandb/apis/normalize.py", line 26, in wrapper
    return func(*args, **kwargs)
  File "/mnt/disk1/anaconda3/envs/longnd/lib/python3.8/site-packages/wandb/sdk/internal/internal_api.py", line 1516, in upsert_run
    response = self.gql(
  File "/mnt/disk1/anaconda3/envs/longnd/lib/python3.8/site-packages/wandb/sdk/lib/retry.py", line 129, in __call__
    retry_timedelta_triggered = check_retry_fn(e)
  File "/mnt/disk1/anaconda3/envs/longnd/lib/python3.8/site-packages/wandb/util.py", line 1049, in check_retry_fn
    return fallback_retry_fn(e)
  File "/mnt/disk1/anaconda3/envs/longnd/lib/python3.8/site-packages/wandb/util.py", line 996, in no_retry_auth
    raise CommError("Permission denied, ask the project owner to grant you access")
wandb.errors.CommError: Permission denied, ask the project owner to grant you access

During handling of the above exception, another exception occurred:

Traceback (most recent call last):
  File "/mnt/disk1/anaconda3/envs/longnd/lib/python3.8/site-packages/wandb/sdk/internal/internal_util.py", line 50, in run
    self._run()
  File "/mnt/disk1/anaconda3/envs/longnd/lib/python3.8/site-packages/wandb/sdk/internal/internal_util.py", line 101, in _run
    self._process(record)
  File "/mnt/disk1/anaconda3/envs/longnd/lib/python3.8/site-packages/wandb/sdk/internal/internal.py", line 308, in _process
    self._sm.send(record)
  File "/mnt/disk1/anaconda3/envs/longnd/lib/python3.8/site-packages/wandb/sdk/internal/sender.py", line 305, in send
    send_handler(record)
  File "/mnt/disk1/anaconda3/envs/longnd/lib/python3.8/site-packages/wandb/sdk/internal/sender.py", line 797, in send_run
    self._init_run(run, config_value_dict)
  File "/mnt/disk1/anaconda3/envs/longnd/lib/python3.8/site-packages/wandb/sdk/internal/sender.py", line 823, in _init_run
    server_run, inserted, server_messages = self._api.upsert_run(
  File "/mnt/disk1/anaconda3/envs/longnd/lib/python3.8/site-packages/wandb/apis/normalize.py", line 62, in wrapper
    raise CommError(message, err).with_traceback(sys.exc_info()[2])
  File "/mnt/disk1/anaconda3/envs/longnd/lib/python3.8/site-packages/wandb/apis/normalize.py", line 26, in wrapper
    return func(*args, **kwargs)
  File "/mnt/disk1/anaconda3/envs/longnd/lib/python3.8/site-packages/wandb/sdk/internal/internal_api.py", line 1516, in upsert_run
    response = self.gql(
  File "/mnt/disk1/anaconda3/envs/longnd/lib/python3.8/site-packages/wandb/sdk/lib/retry.py", line 129, in __call__
    retry_timedelta_triggered = check_retry_fn(e)
  File "/mnt/disk1/anaconda3/envs/longnd/lib/python3.8/site-packages/wandb/util.py", line 1049, in check_retry_fn
    return fallback_retry_fn(e)
  File "/mnt/disk1/anaconda3/envs/longnd/lib/python3.8/site-packages/wandb/util.py", line 996, in no_retry_auth
    raise CommError("Permission denied, ask the project owner to grant you access")
wandb.errors.CommError: Permission denied, ask the project owner to grant you access
