2022-12-21 10:05:03,914 fflow.py initialize [line:252] INFO Using Logger in `utils.logger.basic_logger`
2022-12-21 10:05:03,915 fflow.py initialize [line:253] INFO Initializing fedtask: pill_classification
2022-12-21 10:05:04,122 fflow.py initialize [line:269] INFO Using model `resnet18` in `benchmark.pill_classification.model.resnet18` as the globally shared model.
2022-12-21 10:05:04,123 fflow.py initialize [line:295] INFO Using sampler `threshold_sampler` in `sampler.threshold_sampler` as the globally shared model.
Using cache found in /home/aiotlabws/.cache/torch/hub/pytorch_vision_v0.10.0
2022-12-21 10:05:10,545 fflow.py initialize [line:315] INFO Initializing Clients: 10 clients of `algorithm.fedavg.Client` being created.
2022-12-21 10:05:10,547 fflow.py initialize [line:336] INFO Initializing Server: 1 server of `algorithm.fedavg.Server` being created.
2022-12-21 10:05:10,548 fflow.py initialize [line:349] INFO Ready to start.
2022-12-21 10:05:10,548 fedbase.py run [line:60] INFO --------------Round 1--------------
> /mnt/disk2/ndlong/easyFL/algorithm/fedbase.py(70)run()
-> utils.fmodule.reset_log(utils.fmodule.LOG_WANDB)
2022-12-21 10:05:15,048 basic_logger.py show_current_output [line:134] INFO test_accuracy                 0.0130
2022-12-21 10:05:15,049 basic_logger.py show_current_output [line:134] INFO test_loss                     4.5173
2022-12-21 10:05:15,049 basic_logger.py time_end [line:74] INFO Eval Time Cost:               4.5011s
{'Accuracy/Testing Accuracy': 0.012987012987012988, 'Loss/Testing Loss': 4.517341133216759}
> /mnt/disk2/ndlong/easyFL/algorithm/fedbase.py(72)run()
-> if flw.logger.early_stop():
{'Accuracy/Testing Accuracy': 0.012987012987012988, 'Loss/Testing Loss': 4.517341133216759}
2022-12-21 10:09:05,816 main.py main [line:22] ERROR Exception Logged
Traceback (most recent call last):
  File "main.py", line 22, in main
    server.run()
  File "/mnt/disk2/ndlong/easyFL/algorithm/fedbase.py", line 72, in run
    # utils.fmodule.reset_log(utils.fmodule.LOG_WANDB)
  File "/mnt/disk2/ndlong/easyFL/algorithm/fedbase.py", line 72, in run
    # utils.fmodule.reset_log(utils.fmodule.LOG_WANDB)
  File "/mnt/disk1/anaconda3/envs/longnd/lib/python3.8/bdb.py", line 88, in trace_dispatch
    return self.dispatch_line(frame)
  File "/mnt/disk1/anaconda3/envs/longnd/lib/python3.8/bdb.py", line 113, in dispatch_line
    if self.quitting: raise BdbQuit
bdb.BdbQuit
Traceback (most recent call last):
  File "main.py", line 22, in main
    server.run()
  File "/mnt/disk2/ndlong/easyFL/algorithm/fedbase.py", line 72, in run
    # utils.fmodule.reset_log(utils.fmodule.LOG_WANDB)
  File "/mnt/disk2/ndlong/easyFL/algorithm/fedbase.py", line 72, in run
    # utils.fmodule.reset_log(utils.fmodule.LOG_WANDB)
  File "/mnt/disk1/anaconda3/envs/longnd/lib/python3.8/bdb.py", line 88, in trace_dispatch
    return self.dispatch_line(frame)
  File "/mnt/disk1/anaconda3/envs/longnd/lib/python3.8/bdb.py", line 113, in dispatch_line
    if self.quitting: raise BdbQuit
bdb.BdbQuit
During handling of the above exception, another exception occurred:
Traceback (most recent call last):
  File "main.py", line 31, in <module>
    main()
  File "main.py", line 22, in main
    server.run()
RuntimeError