2022-12-21 12:50:24,405 fflow.py initialize [line:259] INFO Using Logger in `utils.logger.basic_logger`
2022-12-21 12:50:24,406 fflow.py initialize [line:260] INFO Initializing fedtask: pill_classification
2022-12-21 12:50:24,459 fflow.py initialize [line:276] INFO Using model `resnet18` in `benchmark.pill_classification.model.resnet18` as the globally shared model.
2022-12-21 12:50:24,460 fflow.py initialize [line:304] INFO Using sampler `threshold_sampler` in `sampler.threshold_sampler` as the globally shared model.
Using cache found in /home/aiotlabws/.cache/torch/hub/pytorch_vision_v0.10.0
2022-12-21 12:50:31,236 fflow.py initialize [line:324] INFO Initializing Clients: 10 clients of `algorithm.fedalgo3.Client` being created.
2022-12-21 12:50:31,243 fflow.py initialize [line:345] INFO Initializing Server: 1 server of `algorithm.fedalgo3.Server` being created.
2022-12-21 12:50:31,247 fflow.py initialize [line:358] INFO Ready to start.
2022-12-21 12:50:31,248 fedbase.py run [line:61] INFO --------------Round 1--------------
2022-12-21 12:50:46,815 basic_logger.py show_current_output [line:134] INFO test_accuracy                 0.0130
2022-12-21 12:50:46,817 basic_logger.py show_current_output [line:134] INFO test_loss                     4.5173
2022-12-21 12:50:46,817 basic_logger.py time_end [line:74] INFO Eval Time Cost:               15.5686s
2022-12-21 12:50:46,822 fedalgo3.py iterate [line:35] INFO Selected clients : [1, 2]
Using cache found in /home/aiotlabws/.cache/torch/hub/pytorch_vision_v0.10.0
2022-12-21 13:02:56,546 basic_logger.py time_end [line:74] INFO Time Cost:                    745.2975s
2022-12-21 13:02:56,547 fedbase.py run [line:61] INFO --------------Round 2--------------
Total samples which participate training : 1495 samples
2022-12-21 13:03:10,812 basic_logger.py show_current_output [line:134] INFO test_accuracy                 0.2701
2022-12-21 13:03:10,814 basic_logger.py show_current_output [line:134] INFO test_loss                     3.3426
2022-12-21 13:03:10,815 basic_logger.py time_end [line:74] INFO Eval Time Cost:               14.2683s
2022-12-21 13:03:10,820 fedalgo3.py iterate [line:35] INFO Selected clients : [3, 0]
2022-12-21 13:03:43,499 main.py main [line:27] ERROR Exception Logged
Traceback (most recent call last):
  File "main.py", line 24, in main
    server.run()
  File "/mnt/disk2/ndlong/easyFL/algorithm/fedbase.py", line 74, in run
    self.iterate()
  File "/mnt/disk2/ndlong/easyFL/algorithm/fedalgo3.py", line 36, in iterate
    received_information = self.communicate(self.selected_clients)
  File "/mnt/disk2/ndlong/easyFL/algorithm/fedalgo3.py", line 131, in communicate
    response_from_client_id = self.communicate_with(client_id)
  File "/mnt/disk2/ndlong/easyFL/algorithm/fedalgo3.py", line 101, in communicate_with
    return self.clients[client_id].reply(svr_pkg)
  File "/mnt/disk2/ndlong/easyFL/algorithm/fedalgo3.py", line 219, in reply
    historgram_ = self.build_histogram(self.score_cached, self.score_range)
TypeError: build_histogram() takes 2 positional arguments but 3 were given
Traceback (most recent call last):
  File "main.py", line 24, in main
    server.run()
  File "/mnt/disk2/ndlong/easyFL/algorithm/fedbase.py", line 74, in run
    self.iterate()
  File "/mnt/disk2/ndlong/easyFL/algorithm/fedalgo3.py", line 36, in iterate
    received_information = self.communicate(self.selected_clients)
  File "/mnt/disk2/ndlong/easyFL/algorithm/fedalgo3.py", line 131, in communicate
    response_from_client_id = self.communicate_with(client_id)
  File "/mnt/disk2/ndlong/easyFL/algorithm/fedalgo3.py", line 101, in communicate_with
    return self.clients[client_id].reply(svr_pkg)
  File "/mnt/disk2/ndlong/easyFL/algorithm/fedalgo3.py", line 219, in reply
    historgram_ = self.build_histogram(self.score_cached, self.score_range)
TypeError: build_histogram() takes 2 positional arguments but 3 were given
During handling of the above exception, another exception occurred:
Traceback (most recent call last):
  File "main.py", line 33, in <module>
    main()
  File "main.py", line 28, in main
    raise RuntimeError
RuntimeError