2022-12-21 10:15:41,264 fflow.py initialize [line:255] INFO Using Logger in `utils.logger.basic_logger`
2022-12-21 10:15:41,265 fflow.py initialize [line:256] INFO Initializing fedtask: pill_classification
2022-12-21 10:15:41,471 fflow.py initialize [line:272] INFO Using model `resnet18` in `benchmark.pill_classification.model.resnet18` as the globally shared model.
2022-12-21 10:15:41,474 fflow.py initialize [line:298] INFO Using sampler `threshold_sampler` in `sampler.threshold_sampler` as the globally shared model.
Using cache found in /home/aiotlabws/.cache/torch/hub/pytorch_vision_v0.10.0
2022-12-21 10:15:47,874 fflow.py initialize [line:318] INFO Initializing Clients: 10 clients of `algorithm.fedavg.Client` being created.
2022-12-21 10:15:47,876 fflow.py initialize [line:339] INFO Initializing Server: 1 server of `algorithm.fedavg.Server` being created.
2022-12-21 10:15:47,876 fflow.py initialize [line:352] INFO Ready to start.
2022-12-21 10:15:47,877 fedbase.py run [line:61] INFO --------------Round 1--------------
2022-12-21 10:15:51,992 basic_logger.py show_current_output [line:134] INFO test_accuracy                 0.0130
2022-12-21 10:15:51,992 basic_logger.py show_current_output [line:134] INFO test_loss                     4.5173
2022-12-21 10:15:51,992 basic_logger.py time_end [line:74] INFO Eval Time Cost:               4.1155s
2022-12-21 10:15:51,993 fedbase.py iterate [line:107] INFO Selected clients : [1, 2]
Client 1 init its dataloader
Client 2 init its dataloader
Using cache found in /home/aiotlabws/.cache/torch/hub/pytorch_vision_v0.10.0
> /mnt/disk2/ndlong/easyFL/algorithm/fedbase.py(82)run()
-> self.log_file[f"Round {round}"] = utils.fmodule.LOG_DICT
{'selectd_client': [1, 2], 'training_loss': {'client_1': [4.001952237553066, 2.091352343559265, 0.8006153603394827, 0.24847779174645743, 0.09066060309608777], 'client_2': [4.047735095024109, 1.9515314420064291, 0.727062510450681, 0.2398374838133653, 0.10367322651048501]}}
[1, 2]
<class 'list'>
<class 'numpy.int64'>
2022-12-21 10:18:32,380 main.py main [line:24] ERROR Exception Logged
Traceback (most recent call last):
  File "main.py", line 24, in main
    server.run()
  File "/mnt/disk2/ndlong/easyFL/algorithm/fedbase.py", line 82, in run
    self.log_file[f"Round {round}"] = utils.fmodule.LOG_DICT
  File "/mnt/disk2/ndlong/easyFL/algorithm/fedbase.py", line 82, in run
    self.log_file[f"Round {round}"] = utils.fmodule.LOG_DICT
  File "/mnt/disk1/anaconda3/envs/longnd/lib/python3.8/bdb.py", line 88, in trace_dispatch
    return self.dispatch_line(frame)
  File "/mnt/disk1/anaconda3/envs/longnd/lib/python3.8/bdb.py", line 113, in dispatch_line
    if self.quitting: raise BdbQuit
bdb.BdbQuit
Traceback (most recent call last):
  File "main.py", line 24, in main
    server.run()
  File "/mnt/disk2/ndlong/easyFL/algorithm/fedbase.py", line 82, in run
    self.log_file[f"Round {round}"] = utils.fmodule.LOG_DICT
  File "/mnt/disk2/ndlong/easyFL/algorithm/fedbase.py", line 82, in run
    self.log_file[f"Round {round}"] = utils.fmodule.LOG_DICT
  File "/mnt/disk1/anaconda3/envs/longnd/lib/python3.8/bdb.py", line 88, in trace_dispatch
    return self.dispatch_line(frame)
  File "/mnt/disk1/anaconda3/envs/longnd/lib/python3.8/bdb.py", line 113, in dispatch_line
    if self.quitting: raise BdbQuit
bdb.BdbQuit
During handling of the above exception, another exception occurred:
Traceback (most recent call last):
  File "main.py", line 33, in <module>
    main()
  File "main.py", line 24, in main
    server.run()
RuntimeError