2022-12-21 12:30:28,814 fflow.py initialize [line:255] INFO Using Logger in `utils.logger.basic_logger`
2022-12-21 12:30:28,818 fflow.py initialize [line:256] INFO Initializing fedtask: pill_classification
2022-12-21 12:30:28,917 fflow.py initialize [line:272] INFO Using model `resnet18` in `benchmark.pill_classification.model.resnet18` as the globally shared model.
2022-12-21 12:30:28,919 fflow.py initialize [line:298] INFO Using sampler `threshold_sampler` in `sampler.threshold_sampler` as the globally shared model.
Using cache found in /home/aiotlabws/.cache/torch/hub/pytorch_vision_v0.10.0
2022-12-21 12:30:37,573 fflow.py initialize [line:318] INFO Initializing Clients: 10 clients of `algorithm.fedalgo3.Client` being created.
2022-12-21 12:30:37,575 fflow.py initialize [line:339] INFO Initializing Server: 1 server of `algorithm.fedalgo3.Server` being created.
2022-12-21 12:30:37,576 fflow.py initialize [line:352] INFO Ready to start.
2022-12-21 12:30:37,576 fedbase.py run [line:61] INFO --------------Round 1--------------
2022-12-21 12:30:58,190 basic_logger.py show_current_output [line:134] INFO test_accuracy                 0.0130
2022-12-21 12:30:58,192 basic_logger.py show_current_output [line:134] INFO test_loss                     4.5173
2022-12-21 12:30:58,192 basic_logger.py time_end [line:74] INFO Eval Time Cost:               20.6159s
2022-12-21 12:30:58,193 fedalgo3.py iterate [line:34] INFO Selected clients : [1, 2]
2022-12-21 12:30:58,211 main.py main [line:27] ERROR Exception Logged
Traceback (most recent call last):
  File "main.py", line 24, in main
    server.run()
  File "/mnt/disk2/ndlong/easyFL/algorithm/fedbase.py", line 74, in run
    self.iterate()
  File "/mnt/disk2/ndlong/easyFL/algorithm/fedalgo3.py", line 35, in iterate
    received_information = self.communicate(self.selected_clients)
  File "/mnt/disk2/ndlong/easyFL/algorithm/fedalgo3.py", line 138, in communicate
    response_from_client_id = self.communicate_with(client_id)
  File "/mnt/disk2/ndlong/easyFL/algorithm/fedalgo3.py", line 101, in communicate_with
    return self.clients[client_id].reply(svr_pkg)
  File "/mnt/disk2/ndlong/easyFL/algorithm/fedalgo3.py", line 214, in reply
    model, threshold, score_range = self.unpack_model_threshold(svr_pkg)
  File "/mnt/disk2/ndlong/easyFL/algorithm/fedalgo3.py", line 192, in unpack_model_threshold
    return svr_pkg["model"], svr_pkg["threshold"], svr_pkg["score_range"]
KeyError: 'score_range'
Traceback (most recent call last):
  File "main.py", line 24, in main
    server.run()
  File "/mnt/disk2/ndlong/easyFL/algorithm/fedbase.py", line 74, in run
    self.iterate()
  File "/mnt/disk2/ndlong/easyFL/algorithm/fedalgo3.py", line 35, in iterate
    received_information = self.communicate(self.selected_clients)
  File "/mnt/disk2/ndlong/easyFL/algorithm/fedalgo3.py", line 138, in communicate
    response_from_client_id = self.communicate_with(client_id)
  File "/mnt/disk2/ndlong/easyFL/algorithm/fedalgo3.py", line 101, in communicate_with
    return self.clients[client_id].reply(svr_pkg)
  File "/mnt/disk2/ndlong/easyFL/algorithm/fedalgo3.py", line 214, in reply
    model, threshold, score_range = self.unpack_model_threshold(svr_pkg)
  File "/mnt/disk2/ndlong/easyFL/algorithm/fedalgo3.py", line 192, in unpack_model_threshold
    return svr_pkg["model"], svr_pkg["threshold"], svr_pkg["score_range"]
KeyError: 'score_range'
During handling of the above exception, another exception occurred:
Traceback (most recent call last):
  File "main.py", line 33, in <module>
    main()
  File "main.py", line 28, in main
    raise RuntimeError
RuntimeError